Workbook

Sheet Definitions
A1: Metric | B1: Definition | C1: Formula / source
A2: — Sheets overview —
A3: Incoming Trains | B3: One row per inbound train, full lifecycle on a single line (identity, timestamps, derived waits/durations). | C3: tab 2; built by build_incoming_trains_sheet.
A4: Wagon Groups | B4: One row per wagon group, full lifecycle (parent train → classification → parent OBT → departure). | C4: tab 3; built by build_wagon_groups_sheet.
A5: Outbound Trains | B5: One row per outbound train (OBT), full lifecycle on the classification side (OBTP, exit gate, DEPD). | C5: tab 4; built by build_outbound_trains_sheet.
A6: WG Yard Times | B6: Per-WG cross-check of arrival-yard and classification-yard dwell times, with all the supporting timestamps shown. | C6: built by build_wg_yard_times_sheet.
A7: Activities (raw) | B7: One row per completed activity instance. Identity (type, id, entity, length), drive context (from/to/distance), timestamps (initialized/started/completed), duration. | C7: built by build_activities_raw_sheet.
A8: OBTs (raw) / WGs (raw) | B8: Flat rows for outbound trains and classified wagon groups; redundant with the per-entity sheets but kept for legacy cross-references. | C8: built by build_obts_raw_sheet / build_wgs_raw_sheet.
A9: — Incoming Trains KPIs —
A10: Entry Queue wait (hh:mm:ss) | B10: Time the train sat in the entry queue waiting for an arrival track to free up. Pure queue time — does NOT include the drive. | C10: Incoming Trains!M = (E − D) = ArrivalDriveStart − EntryToStation
A11: Arrival drive duration (hh:mm:ss) | B11: Time the train spent physically driving from the entry gate to its assigned arrival track. | C11: Incoming Trains!N = (F − E) = AtArrivalTrack − ArrivalDriveStart
A12: ITP wait (hh:mm:ss) | B12: Time between ITP being submitted to ResourceCU and the work actually commencing. Captures worker + shunt-loco allocation + travel-to-site time. | C12: Incoming Trains!O = (H − G) = ITP_Starts − ITP_Init
A13: ITP duration (hh:mm:ss) | B13: Time the ITP work itself ran, once resources arrived. | C13: Incoming Trains!P = (I − H) = ITP_Ends − ITP_Starts
A14: PushOff wait (hh:mm:ss) | B14: Time between PushOff being submitted and the work actually commencing. Captures worker re-allocation + passage-track wait. | C14: Incoming Trains!Q = (K − J) = PushOff_Starts − PushOff_Init
A15: PushOff duration (hh:mm:ss) | B15: Time the entire PushOff envelope ran (all sub-drives + loco pull-backs between them). | C15: Incoming Trains!R = (L − K) = PushOff_Ends − PushOff_Starts
A16: Total in arrival yard (hh:mm:ss) | B16: Total time the inbound train physically occupied an arrival track (from arrival to last WG pushed off). | C16: Incoming Trains!S = (L − F) = PushOff_Ends − AtArrivalTrack
A17: Total in system (hh:mm:ss) | B17: End-to-end inbound time: from entry-queue arrival until PushOff completed. | C17: Incoming Trains!T = (L − D) = PushOff_Ends − EntryToStation
A18: — Wagon Groups KPIs —
A19: Time in arrival yard (hh:mm:ss) | B19: Time the WG was on the arrival track as part of its parent train, from arrival to being pushed off. | C19: Wagon Groups!M = (G − E) = PushOffDriveEnds − AtArrivalTrack
A20: Time in classification yard (hh:mm:ss) | B20: Time the WG sat on its classification track, from arriving there (= PushOffDrive ends) until the parent OBT physically departed. | C20: Wagon Groups!N = (L − G) = DepartureDriveEnds − PushOffDriveEnds
A21: Idle time on classification track (hh:mm:ss) | B21: Time the WG waits after getting coupled or secured until the OBTP activity starts — the 'doing nothing' window after its own prep is done but before OBT-wide work begins. | C21: Wagon Groups!P = (I − O) = OBTP_Starts − SEC/COP_End
A22: Classification context | B22: Plain-language narrative of the WG's time on the classification track: how it joined (secured first, or coupled to the sibling already there), the wait before each later sibling coupled, the OBTP window, and departure. | C22: Wagon Groups!Q; built in parse_wagon_groups.
A23: — Outbound Trains KPIs —
A24: OBTP wait (hh:mm:ss) | B24: Time between OBTP being submitted and actually starting. Captures worker + train-loco allocation + travel. | C24: Outbound Trains!K = (F − E) = OBTP_Starts − OBTP_Init
A25: OBTP duration (hh:mm:ss) | B25: Time the OBTP work itself ran. | C25: Outbound Trains!L = (G − F) = OBTP_Ends − OBTP_Starts
A26: DEPD gate wait (hh:mm:ss) | B26: Time the OBT was ready to depart (DEPD submitted) but stuck waiting for the single exit-gate resource. Headline bottleneck metric given exitGateCount = 1. | C26: Outbound Trains!M = (I − H) = DEPD_Starts − DEPD_Init
A27: DEPD duration (hh:mm:ss) | B27: Time the train spent physically driving from its classification track to the exit gate. | C27: Outbound Trains!N = (J − I) = DEPD_Ends − DEPD_Starts
A28: Total on classification track (hh:mm:ss) | B28: End-to-end outbound time, from OBT-creation moment (≈ OBTP init) until DEPD completes. | C28: Outbound Trains!O = (J − E) = DEPD_Ends − OBTP_Init
A29: — Activities (raw) reference —
A30: Activity row | B30: One row per completed activity (Started AND Completed present). Pending / cancelled activities are excluded from this sheet. | C30: parse_activity_durations in analytics.py.
A31: From / To / Drive length | B31: Populated only for the three driving activity types (ArrivalDrive, DepartureDrive, PushOffDrive). Distance values come from static maps near the top of analytics.py (ported from C# Models/*DriveActivity.cs and Models/PushOffActivity.cs). | C31: ARRIVAL_DRIVE_DISTANCES + DEPARTURE_DRIVE_DISTANCES + PUSH_ARRIVAL_LEG + PUSH_CLASS_LEG (in analytics.py).
A32: Duration (hh:mm:ss) | B32: Wall-clock time the activity spent in its 'running' state. Rendered as hh:mm:ss across the whole workbook. | C32: Activities (raw)!K = Completed − Started
A33: — Activity type glossary —
A34: Activity type abbreviations | B34: ARRD = ArrivalDrive (train enters yard on own loco); ITP = IncomingTrainPreparation (workers prep arriving train); PO = PushOff (parent envelope); POD = PushOffDrive (one sub-drive per consecutive-same-destination cut of WGs); SEC = Securing (first WG on a classification track); COP = Coupling (joining WG to existing WGs on track); OBTP = OutboundTrainPreparation (workers + train loco prep OBT); DEPD = DepartureDrive (OBT exits through gate). | C34: (reference — see Models/Activity.cs GetActivityAbbreviation).
A35: — WG → OBT matching —
A36: How parent OBT is derived for a WG | B36: WGs are matched to OBTs by classification track + time window: an OBT created at time T on track X owns every WG that arrived on track X at or before T and wasn't already claimed by an earlier OBT on the same track. Greedy, earliest-OBT-first. | C36: parse_obts_and_wgs in analytics.py.

Sheet Overview
A1: Wiener Neustadt Shunting Yard — Overview
A3: — Run summary — | B3: Value
A4: Inbound trains processed | B4: =COUNTA('Incoming Trains'!A:A)-1
A5: OBTs created | B5: =COUNTA('Outbound Trains'!A:A)-1
A6: WGs classified | B6: =COUNTA('Wagon Groups'!A:A)-1
A7: Activity instances logged | B7: =COUNTA('Activities (raw)'!A:A)-1
A8: Sim duration (hh:mm:ss) | B8: 29.77419
A10: — Incoming Trains KPIs (per-train averages) — | B10: Mean | C10: Min | D10: Max | E10: Median
A11: Entry Queue wait | B11: =IFERROR(AVERAGE('Incoming Trains'!M:M),0) | C11: =IFERROR(MIN('Incoming Trains'!M:M),0) | D11: =IFERROR(MAX('Incoming Trains'!M:M),0) | E11: =IFERROR(MEDIAN('Incoming Trains'!M:M),0)
A12: Arrival drive duration | B12: =IFERROR(AVERAGE('Incoming Trains'!N:N),0) | C12: =IFERROR(MIN('Incoming Trains'!N:N),0) | D12: =IFERROR(MAX('Incoming Trains'!N:N),0) | E12: =IFERROR(MEDIAN('Incoming Trains'!N:N),0)
A13: ITP wait | B13: =IFERROR(AVERAGE('Incoming Trains'!O:O),0) | C13: =IFERROR(MIN('Incoming Trains'!O:O),0) | D13: =IFERROR(MAX('Incoming Trains'!O:O),0) | E13: =IFERROR(MEDIAN('Incoming Trains'!O:O),0)
A14: ITP duration | B14: =IFERROR(AVERAGE('Incoming Trains'!P:P),0) | C14: =IFERROR(MIN('Incoming Trains'!P:P),0) | D14: =IFERROR(MAX('Incoming Trains'!P:P),0) | E14: =IFERROR(MEDIAN('Incoming Trains'!P:P),0)
A15: PushOff wait | B15: =IFERROR(AVERAGE('Incoming Trains'!Q:Q),0) | C15: =IFERROR(MIN('Incoming Trains'!Q:Q),0) | D15: =IFERROR(MAX('Incoming Trains'!Q:Q),0) | E15: =IFERROR(MEDIAN('Incoming Trains'!Q:Q),0)
A16: PushOff duration | B16: =IFERROR(AVERAGE('Incoming Trains'!R:R),0) | C16: =IFERROR(MIN('Incoming Trains'!R:R),0) | D16: =IFERROR(MAX('Incoming Trains'!R:R),0) | E16: =IFERROR(MEDIAN('Incoming Trains'!R:R),0)
A17: Total in arrival yard | B17: =IFERROR(AVERAGE('Incoming Trains'!S:S),0) | C17: =IFERROR(MIN('Incoming Trains'!S:S),0) | D17: =IFERROR(MAX('Incoming Trains'!S:S),0) | E17: =IFERROR(MEDIAN('Incoming Trains'!S:S),0)
A18: Total in system | B18: =IFERROR(AVERAGE('Incoming Trains'!T:T),0) | C18: =IFERROR(MIN('Incoming Trains'!T:T),0) | D18: =IFERROR(MAX('Incoming Trains'!T:T),0) | E18: =IFERROR(MEDIAN('Incoming Trains'!T:T),0)
A20: — Wagon Groups KPIs (per-WG averages) — | B20: Mean | C20: Min | D20: Max | E20: Median
A21: Time in arrival yard | B21: =IFERROR(AVERAGE('Wagon Groups'!M:M),0) | C21: =IFERROR(MIN('Wagon Groups'!M:M),0) | D21: =IFERROR(MAX('Wagon Groups'!M:M),0) | E21: =IFERROR(MEDIAN('Wagon Groups'!M:M),0)
A22: Time in classification yard | B22: =IFERROR(AVERAGE('Wagon Groups'!N:N),0) | C22: =IFERROR(MIN('Wagon Groups'!N:N),0) | D22: =IFERROR(MAX('Wagon Groups'!N:N),0) | E22: =IFERROR(MEDIAN('Wagon Groups'!N:N),0)
A23: Idle time on classification track | B23: =IFERROR(AVERAGE('Wagon Groups'!P:P),0) | C23: =IFERROR(MIN('Wagon Groups'!P:P),0) | D23: =IFERROR(MAX('Wagon Groups'!P:P),0) | E23: =IFERROR(MEDIAN('Wagon Groups'!P:P),0)
A25: — Outbound Trains KPIs (per-OBT averages) — | B25: Mean | C25: Min | D25: Max | E25: Median
A26: OBTP wait | B26: =IFERROR(AVERAGE('Outbound Trains'!K:K),0) | C26: =IFERROR(MIN('Outbound Trains'!K:K),0) | D26: =IFERROR(MAX('Outbound Trains'!K:K),0) | E26: =IFERROR(MEDIAN('Outbound Trains'!K:K),0)
A27: OBTP duration | B27: =IFERROR(AVERAGE('Outbound Trains'!L:L),0) | C27: =IFERROR(MIN('Outbound Trains'!L:L),0) | D27: =IFERROR(MAX('Outbound Trains'!L:L),0) | E27: =IFERROR(MEDIAN('Outbound Trains'!L:L),0)
A28: DEPD gate wait | B28: =IFERROR(AVERAGE('Outbound Trains'!M:M),0) | C28: =IFERROR(MIN('Outbound Trains'!M:M),0) | D28: =IFERROR(MAX('Outbound Trains'!M:M),0) | E28: =IFERROR(MEDIAN('Outbound Trains'!M:M),0)
A29: DEPD duration | B29: =IFERROR(AVERAGE('Outbound Trains'!N:N),0) | C29: =IFERROR(MIN('Outbound Trains'!N:N),0) | D29: =IFERROR(MAX('Outbound Trains'!N:N),0) | E29: =IFERROR(MEDIAN('Outbound Trains'!N:N),0)
A30: Total on classification track | B30: =IFERROR(AVERAGE('Outbound Trains'!O:O),0) | C30: =IFERROR(MIN('Outbound Trains'!O:O),0) | D30: =IFERROR(MAX('Outbound Trains'!O:O),0) | E30: =IFERROR(MEDIAN('Outbound Trains'!O:O),0)

Sheet Incoming Trains
A1: ID | B1: Length (m) | C1: Track | D1: Entry to station | E1: Arrival drive start | F1: At arrival track | G1: ITP init | H1: ITP starts | I1: ITP ends | J1: PushOff init | K1: PushOff starts | L1: PushOff ends | M1: Entry Queue wait (hh:mm:ss) | N1: Arrival drive dur (hh:mm:ss) | O1: ITP wait (hh:mm:ss) | P1: ITP duration (hh:mm:ss) | Q1: PushOff wait (hh:mm:ss) | R1: PushOff duration (hh:mm:ss) | S1: Total in arrival yard (hh:mm:ss) | T1: Total in system (hh:mm:ss)
A2: 10001 | B2: 227.02 | C2: 703 | D2: 45659.111 | E2: 45659.111 | F2: 45659.113 | G2: 45659.113 | H2: 45659.116 | I2: 45659.12 | J2: 45659.12 | K2: 45659.121 | L2: 45659.128 | M2: =IF(AND(ISNUMBER(D2),ISNUMBER(E2)),(E2-D2),"") | N2: =IF(AND(ISNUMBER(E2),ISNUMBER(F2)),(F2-E2),"") | O2: =IF(AND(ISNUMBER(G2),ISNUMBER(H2)),(H2-G2),"") | P2: =IF(AND(ISNUMBER(H2),ISNUMBER(I2)),(I2-H2),"") | Q2: =IF(AND(ISNUMBER(J2),ISNUMBER(K2)),(K2-J2),"") | R2: =IF(AND(ISNUMBER(K2),ISNUMBER(L2)),(L2-K2),"") | S2: =IF(AND(ISNUMBER(F2),ISNUMBER(L2)),(L2-F2),"") | T2: =IF(AND(ISNUMBER(D2),ISNUMBER(L2)),(L2-D2),"")
A3: 10002 | B3: 182.7 | C3: 703 | D3: 45659.269 | E3: 45659.269 | F3: 45659.271 | G3: 45659.271 | H3: 45659.274 | I3: 45659.275 | J3: 45659.275 | K3: 45659.276 | L3: 45659.278 | M3: =IF(AND(ISNUMBER(D3),ISNUMBER(E3)),(E3-D3),"") | N3: =IF(AND(ISNUMBER(E3),ISNUMBER(F3)),(F3-E3),"") | O3: =IF(AND(ISNUMBER(G3),ISNUMBER(H3)),(H3-G3),"") | P3: =IF(AND(ISNUMBER(H3),ISNUMBER(I3)),(I3-H3),"") | Q3: =IF(AND(ISNUMBER(J3),ISNUMBER(K3)),(K3-J3),"") | R3: =IF(AND(ISNUMBER(K3),ISNUMBER(L3)),(L3-K3),"") | S3: =IF(AND(ISNUMBER(F3),ISNUMBER(L3)),(L3-F3),"") | T3: =IF(AND(ISNUMBER(D3),ISNUMBER(L3)),(L3-D3),"")
A4: 10003 | B4: 578.18 | C4: 727 | D4: 45659.298 | E4: 45659.298 | F4: 45659.3 | G4: 45659.3 | H4: 45659.303 | I4: 45659.318 | J4: 45659.318 | K4: 45659.319 | L4: 45659.339 | M4: =IF(AND(ISNUMBER(D4),ISNUMBER(E4)),(E4-D4),"") | N4: =IF(AND(ISNUMBER(E4),ISNUMBER(F4)),(F4-E4),"") | O4: =IF(AND(ISNUMBER(G4),ISNUMBER(H4)),(H4-G4),"") | P4: =IF(AND(ISNUMBER(H4),ISNUMBER(I4)),(I4-H4),"") | Q4: =IF(AND(ISNUMBER(J4),ISNUMBER(K4)),(K4-J4),"") | R4: =IF(AND(ISNUMBER(K4),ISNUMBER(L4)),(L4-K4),"") | S4: =IF(AND(ISNUMBER(F4),ISNUMBER(L4)),(L4-F4),"") | T4: =IF(AND(ISNUMBER(D4),ISNUMBER(L4)),(L4-D4),"")
A5: 10004 | B5: 188.96 | C5: 703 | D5: 45659.307 | E5: 45659.307 | F5: 45659.309 | G5: 45659.309 | H5: 45659.312 | I5: 45659.313 | J5: 45659.313 | K5: 45659.314 | L5: 45659.316 | M5: =IF(AND(ISNUMBER(D5),ISNUMBER(E5)),(E5-D5),"") | N5: =IF(AND(ISNUMBER(E5),ISNUMBER(F5)),(F5-E5),"") | O5: =IF(AND(ISNUMBER(G5),ISNUMBER(H5)),(H5-G5),"") | P5: =IF(AND(ISNUMBER(H5),ISNUMBER(I5)),(I5-H5),"") | Q5: =IF(AND(ISNUMBER(J5),ISNUMBER(K5)),(K5-J5),"") | R5: =IF(AND(ISNUMBER(K5),ISNUMBER(L5)),(L5-K5),"") | S5: =IF(AND(ISNUMBER(F5),ISNUMBER(L5)),(L5-F5),"") | T5: =IF(AND(ISNUMBER(D5),ISNUMBER(L5)),(L5-D5),"")
A6: 10005 | B6: 396.56 | C6: 703 | D6: 45659.334 | E6: 45659.334 | F6: 45659.336 | G6: 45659.336 | H6: 45659.339 | I6: 45659.342 | J6: 45659.342 | K6: 45659.343 | L6: 45659.345 | M6: =IF(AND(ISNUMBER(D6),ISNUMBER(E6)),(E6-D6),"") | N6: =IF(AND(ISNUMBER(E6),ISNUMBER(F6)),(F6-E6),"") | O6: =IF(AND(ISNUMBER(G6),ISNUMBER(H6)),(H6-G6),"") | P6: =IF(AND(ISNUMBER(H6),ISNUMBER(I6)),(I6-H6),"") | Q6: =IF(AND(ISNUMBER(J6),ISNUMBER(K6)),(K6-J6),"") | R6: =IF(AND(ISNUMBER(K6),ISNUMBER(L6)),(L6-K6),"") | S6: =IF(AND(ISNUMBER(F6),ISNUMBER(L6)),(L6-F6),"") | T6: =IF(AND(ISNUMBER(D6),ISNUMBER(L6)),(L6-D6),"")
A7: 10006 | B7: 440.26 | C7: 703 | D7: 45659.367 | E7: 45659.367 | F7: 45659.37 | G7: 45659.37 | H7: 45659.372 | I7: 45659.386 | J7: 45659.386 | K7: 45659.388 | L7: 45659.406 | M7: =IF(AND(ISNUMBER(D7),ISNUMBER(E7)),(E7-D7),"") | N7: =IF(AND(ISNUMBER(E7),ISNUMBER(F7)),(F7-E7),"") | O7: =IF(AND(ISNUMBER(G7),ISNUMBER(H7)),(H7-G7),"") | P7: =IF(AND(ISNUMBER(H7),ISNUMBER(I7)),(I7-H7),"") | Q7: =IF(AND(ISNUMBER(J7),ISNUMBER(K7)),(K7-J7),"") | R7: =IF(AND(ISNUMBER(K7),ISNUMBER(L7)),(L7-K7),"") | S7: =IF(AND(ISNUMBER(F7),ISNUMBER(L7)),(L7-F7),"") | T7: =IF(AND(ISNUMBER(D7),ISNUMBER(L7)),(L7-D7),"")
A8: 10007 | B8: 212.7 | C8: 727 | D8: 45659.375 | E8: 45659.375 | F8: 45659.377 | G8: 45659.377 | H8: 45659.38 | I8: 45659.382 | J8: 45659.382 | K8: 45659.383 | L8: 45659.387 | M8: =IF(AND(ISNUMBER(D8),ISNUMBER(E8)),(E8-D8),"") | N8: =IF(AND(ISNUMBER(E8),ISNUMBER(F8)),(F8-E8),"") | O8: =IF(AND(ISNUMBER(G8),ISNUMBER(H8)),(H8-G8),"") | P8: =IF(AND(ISNUMBER(H8),ISNUMBER(I8)),(I8-H8),"") | Q8: =IF(AND(ISNUMBER(J8),ISNUMBER(K8)),(K8-J8),"") | R8: =IF(AND(ISNUMBER(K8),ISNUMBER(L8)),(L8-K8),"") | S8: =IF(AND(ISNUMBER(F8),ISNUMBER(L8)),(L8-F8),"") | T8: =IF(AND(ISNUMBER(D8),ISNUMBER(L8)),(L8-D8),"")
A9: 10008 | B9: 387.06 | C9: 703 | D9: 45659.437 | E9: 45659.437 | F9: 45659.439 | G9: 45659.439 | H9: 45659.442 | I9: 45659.447 | J9: 45659.447 | K9: 45659.448 | L9: 45659.453 | M9: =IF(AND(ISNUMBER(D9),ISNUMBER(E9)),(E9-D9),"") | N9: =IF(AND(ISNUMBER(E9),ISNUMBER(F9)),(F9-E9),"") | O9: =IF(AND(ISNUMBER(G9),ISNUMBER(H9)),(H9-G9),"") | P9: =IF(AND(ISNUMBER(H9),ISNUMBER(I9)),(I9-H9),"") | Q9: =IF(AND(ISNUMBER(J9),ISNUMBER(K9)),(K9-J9),"") | R9: =IF(AND(ISNUMBER(K9),ISNUMBER(L9)),(L9-K9),"") | S9: =IF(AND(ISNUMBER(F9),ISNUMBER(L9)),(L9-F9),"") | T9: =IF(AND(ISNUMBER(D9),ISNUMBER(L9)),(L9-D9),"")
A10: 10009 | B10: 287.12 | C10: 703 | D10: 45659.607 | E10: 45659.607 | F10: 45659.609 | G10: 45659.609 | H10: 45659.612 | I10: 45659.615 | J10: 45659.615 | K10: 45659.615 | L10: 45659.617 | M10: =IF(AND(ISNUMBER(D10),ISNUMBER(E10)),(E10-D10),"") | N10: =IF(AND(ISNUMBER(E10),ISNUMBER(F10)),(F10-E10),"") | O10: =IF(AND(ISNUMBER(G10),ISNUMBER(H10)),(H10-G10),"") | P10: =IF(AND(ISNUMBER(H10),ISNUMBER(I10)),(I10-H10),"") | Q10: =IF(AND(ISNUMBER(J10),ISNUMBER(K10)),(K10-J10),"") | R10: =IF(AND(ISNUMBER(K10),ISNUMBER(L10)),(L10-K10),"") | S10: =IF(AND(ISNUMBER(F10),ISNUMBER(L10)),(L10-F10),"") | T10: =IF(AND(ISNUMBER(D10),ISNUMBER(L10)),(L10-D10),"")
A11: 10010 | B11: 571.9 | C11: 727 | D11: 45659.625 | E11: 45659.625 | F11: 45659.627 | G11: 45659.627 | H11: 45659.63 | I11: 45659.642 | J11: 45659.642 | K11: 45659.643 | L11: 45659.657 | M11: =IF(AND(ISNUMBER(D11),ISNUMBER(E11)),(E11-D11),"") | N11: =IF(AND(ISNUMBER(E11),ISNUMBER(F11)),(F11-E11),"") | O11: =IF(AND(ISNUMBER(G11),ISNUMBER(H11)),(H11-G11),"") | P11: =IF(AND(ISNUMBER(H11),ISNUMBER(I11)),(I11-H11),"") | Q11: =IF(AND(ISNUMBER(J11),ISNUMBER(K11)),(K11-J11),"") | R11: =IF(AND(ISNUMBER(K11),ISNUMBER(L11)),(L11-K11),"") | S11: =IF(AND(ISNUMBER(F11),ISNUMBER(L11)),(L11-F11),"") | T11: =IF(AND(ISNUMBER(D11),ISNUMBER(L11)),(L11-D11),"")
A12: 10011 | B12: 267.58 | C12: 703 | D12: 45659.626 | E12: 45659.626 | F12: 45659.629 | G12: 45659.629 | H12: 45659.631 | I12: 45659.634 | J12: 45659.634 | K12: 45659.634 | L12: 45659.637 | M12: =IF(AND(ISNUMBER(D12),ISNUMBER(E12)),(E12-D12),"") | N12: =IF(AND(ISNUMBER(E12),ISNUMBER(F12)),(F12-E12),"") | O12: =IF(AND(ISNUMBER(G12),ISNUMBER(H12)),(H12-G12),"") | P12: =IF(AND(ISNUMBER(H12),ISNUMBER(I12)),(I12-H12),"") | Q12: =IF(AND(ISNUMBER(J12),ISNUMBER(K12)),(K12-J12),"") | R12: =IF(AND(ISNUMBER(K12),ISNUMBER(L12)),(L12-K12),"") | S12: =IF(AND(ISNUMBER(F12),ISNUMBER(L12)),(L12-F12),"") | T12: =IF(AND(ISNUMBER(D12),ISNUMBER(L12)),(L12-D12),"")
A13: 10012 | B13: 580.98 | C13: 727 | D13: 45659.737 | E13: 45659.737 | F13: 45659.74 | G13: 45659.74 | H13: 45659.742 | I13: 45659.758 | J13: 45659.758 | K13: 45659.759 | L13: 45659.779 | M13: =IF(AND(ISNUMBER(D13),ISNUMBER(E13)),(E13-D13),"") | N13: =IF(AND(ISNUMBER(E13),ISNUMBER(F13)),(F13-E13),"") | O13: =IF(AND(ISNUMBER(G13),ISNUMBER(H13)),(H13-G13),"") | P13: =IF(AND(ISNUMBER(H13),ISNUMBER(I13)),(I13-H13),"") | Q13: =IF(AND(ISNUMBER(J13),ISNUMBER(K13)),(K13-J13),"") | R13: =IF(AND(ISNUMBER(K13),ISNUMBER(L13)),(L13-K13),"") | S13: =IF(AND(ISNUMBER(F13),ISNUMBER(L13)),(L13-F13),"") | T13: =IF(AND(ISNUMBER(D13),ISNUMBER(L13)),(L13-D13),"")
... A332: 10331 | B332: 351.04 | C332: 703 | D332: 45688.837 | E332: 45688.837 | F332: 45688.839 | G332: 45688.839 | H332: 45688.842 | I332: 45688.85 | J332: 45688.85 | K332: 45688.851 | L332: 45688.862 | M332: =IF(AND(ISNUMBER(D332),ISNUMBER(E332)),(E332-D332),"") | N332: =IF(AND(ISNUMBER(E332),ISNUMBER(F332)),(F332-E332),"") | O332: =IF(AND(ISNUMBER(G332),ISNUMBER(H332)),(H332-G332),"") | P332: =IF(AND(ISNUMBER(H332),ISNUMBER(I332)),(I332-H332),"") | Q332: =IF(AND(ISNUMBER(J332),ISNUMBER(K332)),(K332-J332),"") | R332: =IF(AND(ISNUMBER(K332),ISNUMBER(L332)),(L332-K332),"") | S332: =IF(AND(ISNUMBER(F332),ISNUMBER(L332)),(L332-F332),"") | T332: =IF(AND(ISNUMBER(D332),ISNUMBER(L332)),(L332-D332),"")

Sheet Wagon Groups
A1: ID | B1: Parent incoming train | C1: Length (m) | D1: Destination | E1: At arrival track | F1: PushOffDrive starts | G1: PushOffDrive ends | H1: Parent outbound train | I1: OBTP starts | J1: OBTP ends | K1: Departure drive starts | L1: Departure drive ends | M1: Time in arrival yard (hh:mm:ss) | N1: Time in classification yard (hh:mm:ss) | O1: SEC/COP end | P1: Idle time on classification track (hh:mm:ss) | Q1: Classification context
A2: 1000101 | B2: 10001 | C2: 19.9 | D2: Other sidings south | E2: 45659.113 | F2: 45659.121 | G2: 45659.122 | H2: OBT030125061555-Other sidings south | I2: 45660.263 | J2: 45660.281 | K2: 45660.281 | L2: 45660.281 | M2: =IF(AND(ISNUMBER(E2),ISNUMBER(G2)),(G2-E2),"") | N2: =IF(AND(ISNUMBER(G2),ISNUMBER(L2)),(L2-G2),"") | O2: 45659.124 | P2: =IF(AND(ISNUMBER(I2),ISNUMBER(O2)),(I2-O2),"") | Q2: WG 1000101 entered track and got secured then waited 4:47:39 for WG 1000301 to get coupled then waited 10:33:50 for WG 1001201 to get coupled then waited 8:42:56 for WG 1001402 to get coupled then waited 0:04:13 for WG 1001404 to get coupled then waited 3:08:11 for WG 1001604 to get coupled, OBTP started on 06:18:17 finished on 06:43:58 and then left at 06:44:59
A3: 1000102 | B3: 10001 | C3: 103.9 | D3: Neunkirchen (loading tracks) | E3: 45659.113 | F3: 45659.122 | G3: 45659.124 | H3: OBT020125030112-Neunkirchen (loading tracks) | I3: 45659.127 | J3: 45659.145 | K3: 45659.145 | L3: 45659.145 | M3: =IF(AND(ISNUMBER(E3),ISNUMBER(G3)),(G3-E3),"") | N3: =IF(AND(ISNUMBER(G3),ISNUMBER(L3)),(L3-G3),"") | O3: 45659.126 | P3: =IF(AND(ISNUMBER(I3),ISNUMBER(O3)),(I3-O3),"") | Q3: WG 1000102 entered track and got secured, OBTP started on 03:02:27 finished on 03:28:25 and then left at 03:29:23
A4: 1000103 | B4: 10001 | C4: 71.74 | D4: Ternitz (Schoeller-Bleckmann) | E4: 45659.113 | F4: 45659.124 | G4: 45659.126 | H4: OBT020125152222-Ternitz (Schoeller-Bleckmann) | I4: 45659.641 | J4: 45659.704 | K4: 45659.705 | L4: 45659.706 | M4: =IF(AND(ISNUMBER(E4),ISNUMBER(G4)),(G4-E4),"") | N4: =IF(AND(ISNUMBER(G4),ISNUMBER(L4)),(L4-G4),"") | O4: 45659.128 | P4: =IF(AND(ISNUMBER(I4),ISNUMBER(O4)),(I4-O4),"") | Q4: WG 1000103 entered track and got secured then waited 4:51:04 for WG 1000304 to get coupled then waited 1:47:17 for WG 1000606 to get coupled then waited 5:39:51 for WG 1001101 to get coupled, OBTP started on 15:23:36 finished on 16:54:27 and then left at 16:56:24
A5: 1000104 | B5: 10001 | C5: 31.48 | D5: Gloggnitz | E5: 45659.113 | F5: 45659.126 | G5: 45659.128 | H5: OBT030125063005-Gloggnitz | I5: 45660.277 | J5: 45660.313 | K5: 45660.313 | L5: 45660.314 | M5: =IF(AND(ISNUMBER(E5),ISNUMBER(G5)),(G5-E5),"") | N5: =IF(AND(ISNUMBER(G5),ISNUMBER(L5)),(L5-G5),"") | O5: 45659.13 | P5: =IF(AND(ISNUMBER(I5),ISNUMBER(O5)),(I5-O5),"") | Q5: WG 1000104 entered track and got secured then waited 6:47:00 for WG 1000610 to get coupled then waited 8:29:19 for WG 1001202 to get coupled then waited 2:22:59 for WG 1001302 to get coupled then waited 9:43:40 for WG 1001609 to get coupled, OBTP started on 06:39:21 finished on 07:30:31 and then left at 07:31:55
A6: 1000201 | B6: 10002 | C6: 182.7 | D6: Wien Kledering | E6: 45659.271 | F6: 45659.276 | G6: 45659.278 | H6: OBT020125064334-Wien Kledering | I6: 45659.281 | J6: 45659.313 | K6: 45659.313 | L6: 45659.314 | M6: =IF(AND(ISNUMBER(E6),ISNUMBER(G6)),(G6-E6),"") | N6: =IF(AND(ISNUMBER(G6),ISNUMBER(L6)),(L6-G6),"") | O6: 45659.28 | P6: =IF(AND(ISNUMBER(I6),ISNUMBER(O6)),(I6-O6),"") | Q6: WG 1000201 entered track and got secured, OBTP started on 06:44:47 finished on 07:30:27 and then left at 07:31:41
A7: 1000301 | B7: 10003 | C7: 15.74 | D7: Other sidings south | E7: 45659.3 | F7: 45659.319 | G7: 45659.32 | H7: OBT030125061555-Other sidings south | I7: 45660.263 | J7: 45660.281 | K7: 45660.281 | L7: 45660.281 | M7: =IF(AND(ISNUMBER(E7),ISNUMBER(G7)),(G7-E7),"") | N7: =IF(AND(ISNUMBER(G7),ISNUMBER(L7)),(L7-G7),"") | O7: 45659.324 | P7: =IF(AND(ISNUMBER(I7),ISNUMBER(O7)),(I7-O7),"") | Q7: WG 1000301 entered track and got coupled to WG 1000101 then waited 10:33:50 for WG 1001201 to get coupled then waited 8:42:56 for WG 1001402 to get coupled then waited 0:04:13 for WG 1001404 to get coupled then waited 3:08:11 for WG 1001604 to get coupled, OBTP started on 06:18:17 finished on 06:43:58 and then left at 06:44:59
A8: 1000302 | B8: 10003 | C8: 264.62 | D8: Pitten (Hamburger) | E8: 45659.3 | F8: 45659.32 | G8: 45659.322 | H8: OBT020125074750-Pitten (Hamburger) | I8: 45659.326 | J8: 45659.372 | K8: 45659.372 | L8: 45659.373 | M8: =IF(AND(ISNUMBER(E8),ISNUMBER(G8)),(G8-E8),"") | N8: =IF(AND(ISNUMBER(G8),ISNUMBER(L8)),(L8-G8),"") | O8: 45659.325 | P8: =IF(AND(ISNUMBER(I8),ISNUMBER(O8)),(I8-O8),"") | Q8: WG 1000302 entered track and got secured, OBTP started on 07:49:15 finished on 08:55:24 and then left at 08:57:09
A9: 1000303 | B9: 10003 | C9: 21 | D9: Neunkirchen (loading tracks) | E9: 45659.3 | F9: 45659.322 | G9: 45659.324 | H9: OBT020125184418-Neunkirchen (loading tracks) | I9: 45659.784 | J9: 45659.802 | K9: 45659.802 | L9: 45659.803 | M9: =IF(AND(ISNUMBER(E9),ISNUMBER(G9)),(G9-E9),"") | N9: =IF(AND(ISNUMBER(G9),ISNUMBER(L9)),(L9-G9),"") | O9: 45659.327 | P9: =IF(AND(ISNUMBER(I9),ISNUMBER(O9)),(I9-O9),"") | Q9: WG 1000303 entered track and got secured then waited 0:17:26 for WG 1000309 to get coupled then waited 7:40:59 for WG 1001007 to get coupled then waited 2:55:35 for WG 1001210 to get coupled, OBTP started on 18:49:02 finished on 19:14:44 and then left at 19:15:51
A10: 1000304 | B10: 10003 | C10: 12.04 | D10: Ternitz (Schoeller-Bleckmann) | E10: 45659.3 | F10: 45659.324 | G10: 45659.326 | H10: OBT020125152222-Ternitz (Schoeller-Bleckmann) | I10: 45659.641 | J10: 45659.704 | K10: 45659.705 | L10: 45659.706 | M10: =IF(AND(ISNUMBER(E10),ISNUMBER(G10)),(G10-E10),"") | N10: =IF(AND(ISNUMBER(G10),ISNUMBER(L10)),(L10-G10),"") | O10: 45659.33 | P10: =IF(AND(ISNUMBER(I10),ISNUMBER(O10)),(I10-O10),"") | Q10: WG 1000304 entered track and got coupled to WG 1000103 then waited 1:47:17 for WG 1000606 to get coupled then waited 5:39:51 for WG 1001101 to get coupled, OBTP started on 15:23:36 finished on 16:54:27 and then left at 16:56:24
A11: 1000305 | B11: 10003 | C11: 98.6 | D11: Other sidings north | E11: 45659.3 | F11: 45659.326 | G11: 45659.328 | H11: OBT020125093208-Other sidings north | I11: 45659.414 | J11: 45659.438 | K11: 45659.438 | L11: 45659.438 | M11: =IF(AND(ISNUMBER(E11),ISNUMBER(G11)),(G11-E11),"") | N11: =IF(AND(ISNUMBER(G11),ISNUMBER(L11)),(L11-G11),"") | O11: 45659.331 | P11: =IF(AND(ISNUMBER(I11),ISNUMBER(O11)),(I11-O11),"") | Q11: WG 1000305 entered track and got secured then waited 1:36:05 for WG 1000603 to get coupled, OBTP started on 09:56:37 finished on 10:30:10 and then left at 10:31:25
A12: 1000306 | B12: 10003 | C12: 21 | D12: Neudörfl (FunderMax) | E12: 45659.3 | F12: 45659.328 | G12: 45659.33 | H12: OBT020125154035-Neudörfl (FunderMax) | I12: 45659.662 | J12: 45659.682 | K12: 45659.682 | L12: 45659.683 | M12: =IF(AND(ISNUMBER(E12),ISNUMBER(G12)),(G12-E12),"") | N12: =IF(AND(ISNUMBER(G12),ISNUMBER(L12)),(L12-G12),"") | O12: 45659.333 | P12: =IF(AND(ISNUMBER(I12),ISNUMBER(O12)),(I12-O12),"") | Q12: WG 1000306 entered track and got secured then waited 0:14:38 for WG 1000311 to get coupled then waited 1:11:18 for WG 1000601 to get coupled then waited 0:09:45 for WG 1000604 to get coupled then waited 6:04:58 for WG 1001004 to get coupled, OBTP started on 15:53:17 finished on 16:21:59 and then left at 16:23:06
A13: 1000307 | B13: 10003 | C13: 15.74 | D13: Other sidings local | E13: 45659.3 | F13: 45659.33 | G13: 45659.332 | H13: OBT030125205107-Other sidings local | I13: 45660.895 | J13: 45660.915 | K13: 45660.915 | L13: 45660.916 | M13: =IF(AND(ISNUMBER(E13),ISNUMBER(G13)),(G13-E13),"") | N13: =IF(AND(ISNUMBER(G13),ISNUMBER(L13)),(L13-G13),"") | O13: 45659.334 | P13: =IF(AND(ISNUMBER(I13),ISNUMBER(O13)),(I13-O13),"") | Q13: WG 1000307 entered track and got secured then waited 1:27:56 for WG 1000602 to get coupled then waited 8:58:50 for WG 1001204 to get coupled then waited 11:41:53 for WG 1001601 to get coupled then waited 1:49:03 for WG 1001807 to get coupled then waited 12:52:38 for WG 1002807 to get coupled, OBTP started on 21:28:27 finished on 21:57:12 and then left at 21:58:27
... A636: 1016710 | B636: 10167 | C636: 15.74 | D636: Other sidings north | E636: 45674.362 | F636: 45674.396 | G636: 45674.398 | H636: OBT170125093812-Neudörfl (FunderMax) | I636: 45676.748 | J636: 45676.78 | K636: 45676.78 | L636: 45676.781 | M636: =IF(AND(ISNUMBER(E636),ISNUMBER(G636)),(G636-E636),"") | N636: =IF(AND(ISNUMBER(G636),ISNUMBER(L636)),(L636-G636),"") | O636: 45674.402 | P636: =IF(AND(ISNUMBER(I636),ISNUMBER(O636)),(I636-O636),"") | Q636: WG 1016710 entered track and got coupled to WG 1016708, OBTP started on 17:57:00 finished on 18:43:09 and then left at 18:44:18
A637: 1016801 | B637: 10168 | C637: 163.2 | D637: Wien Kledering | E637: 45674.369 | M637: =IF(AND(ISNUMBER(E637),ISNUMBER(G637)),(G637-E637),"") | N637: =IF(AND(ISNUMBER(G637),ISNUMBER(L637)),(L637-G637),"") | P637: =IF(AND(ISNUMBER(I637),ISNUMBER(O637)),(I637-O637),"")
A638: 1016802 | B638: 10168 | C638: 173.3 | D638: St. Veit an der Glan | E638: 45674.369 | F638: 45674.376 | G638: 45674.377 | H638: OBT170125090658-St. Veit an der Glan | I638: 45675.036 | J638: 45675.067 | K638: 45675.067 | L638: 45675.067 | M638: =IF(AND(ISNUMBER(E638),ISNUMBER(G638)),(G638-E638),"") | N638: =IF(AND(ISNUMBER(G638),ISNUMBER(L638)),(L638-G638),"") | O638: 45674.38 | P638: =IF(AND(ISNUMBER(I638),ISNUMBER(O638)),(I638-O638),"") | Q638: WG 1016802 entered track and got secured, OBTP started on 00:52:28 finished on 01:35:47 and then left at 01:37:02
A639: 1016901 | B639: 10169 | C639: 21 | D639: St. Veit an der Glan | E639: 45674.426 | F639: 45674.434 | G639: 45674.435 | H639: OBT170125174751-Wien Kledering | I639: 45677.201 | J639: 45677.254 | K639: 45677.254 | L639: 45677.255 | M639: =IF(AND(ISNUMBER(E639),ISNUMBER(G639)),(G639-E639),"") | N639: =IF(AND(ISNUMBER(G639),ISNUMBER(L639)),(L639-G639),"") | O639: 45674.438 | P639: =IF(AND(ISNUMBER(I639),ISNUMBER(O639)),(I639-O639),"") | Q639: WG 1016901 entered track and got secured then waited 7:17:38 for WG 1017201 to get coupled, OBTP started on 04:49:55 finished on 06:05:27 and then left at 06:07:07
A640: 1016902 | B640: 10169 | C640: 422.2 | D640: Wien Kledering | E640: 45674.426 | M640: =IF(AND(ISNUMBER(E640),ISNUMBER(G640)),(G640-E640),"") | N640: =IF(AND(ISNUMBER(G640),ISNUMBER(L640)),(L640-G640),"") | P640: =IF(AND(ISNUMBER(I640),ISNUMBER(O640)),(I640-O640),"")
A641: 1017001 | B641: 10170 | C641: 238.44 | D641: Wien Kledering | E641: 45674.536 | F641: 45674.542 | G641: 45674.544 | H641: OBT170125130627-Wien Kledering | I641: 45676.856 | J641: 45676.897 | K641: 45676.897 | L641: 45676.898 | M641: =IF(AND(ISNUMBER(E641),ISNUMBER(G641)),(G641-E641),"") | N641: =IF(AND(ISNUMBER(G641),ISNUMBER(L641)),(L641-G641),"") | O641: 45674.546 | P641: =IF(AND(ISNUMBER(I641),ISNUMBER(O641)),(I641-O641),"") | Q641: WG 1017001 entered track and got secured, OBTP started on 20:32:10 finished on 21:31:47 and then left at 21:33:11
A642: 1017101 | B642: 10171 | C642: 220.36 | D642: Wien Kledering | E642: 45674.65 | F642: 45674.655 | G642: 45674.658 | H642: OBT170125155040-Wien Kledering | I642: 45677.123 | J642: 45677.161 | K642: 45677.161 | L642: 45677.162 | M642: =IF(AND(ISNUMBER(E642),ISNUMBER(G642)),(G642-E642),"") | N642: =IF(AND(ISNUMBER(G642),ISNUMBER(L642)),(L642-G642),"") | O642: 45674.66 | P642: =IF(AND(ISNUMBER(I642),ISNUMBER(O642)),(I642-O642),"") | Q642: WG 1017101 entered track and got secured, OBTP started on 02:56:44 finished on 03:51:49 and then left at 03:53:17
A643: 1017201 | B643: 10172 | C643: 302.12 | D643: Wien Kledering | E643: 45674.731 | F643: 45674.737 | G643: 45674.739 | H643: OBT170125174751-Wien Kledering | I643: 45677.201 | J643: 45677.254 | K643: 45677.254 | L643: 45677.255 | M643: =IF(AND(ISNUMBER(E643),ISNUMBER(G643)),(G643-E643),"") | N643: =IF(AND(ISNUMBER(G643),ISNUMBER(L643)),(L643-G643),"") | O643: 45674.742 | P643: =IF(AND(ISNUMBER(I643),ISNUMBER(O643)),(I643-O643),"") | Q643: WG 1017201 entered track and got secured, OBTP started on 04:49:55 finished on 06:05:27 and then left at 06:07:07
A644: 1017301 | B644: 10173 | C644: 110.18 | D644: Wien Kledering | E644: 45674.752 | F644: 45674.756 | G644: 45674.758 | H644: OBT170125181531-Wien Kledering | I644: 45677.257 | J644: 45677.276 | K644: 45677.276 | L644: 45677.277 | M644: =IF(AND(ISNUMBER(E644),ISNUMBER(G644)),(G644-E644),"") | N644: =IF(AND(ISNUMBER(G644),ISNUMBER(L644)),(L644-G644),"") | O644: 45674.761 | P644: =IF(AND(ISNUMBER(I644),ISNUMBER(O644)),(I644-O644),"") | Q644: WG 1017301 entered track and got secured, OBTP started on 06:10:11 finished on 06:37:43 and then left at 06:38:53
A645: 1017401 | B645: 10174 | C645: 15.74 | D645: Ebenfurth (beet loading) | E645: 45674.84 | F645: 45674.853 | G645: 45674.855 | H645: OBT200125045059-Neudörfl (FunderMax) | I645: 45677.666 | J645: 45677.723 | K645: 45677.723 | L645: 45677.725 | M645: =IF(AND(ISNUMBER(E645),ISNUMBER(G645)),(G645-E645),"") | N645: =IF(AND(ISNUMBER(G645),ISNUMBER(L645)),(L645-G645),"") | O645: 45674.858 | P645: =IF(AND(ISNUMBER(I645),ISNUMBER(O645)),(I645-O645),"") | Q645: WG 1017401 entered track and got secured then waited 9:32:32 for WG 1017601 to get coupled then waited 0:53:12 for WG 1017701 to get coupled then waited 45:50:13 for WG 1018101 to get coupled, OBTP started on 15:59:05 finished on 17:21:30 and then left at 17:23:20
A646: 1017402 | B646: 10174 | C646: 36.4 | D646: Neudörfl (FunderMax) | E646: 45674.84 | F646: 45674.855 | G646: 45674.857 | H646: OBT180125005504-Neudörfl (FunderMax) | I646: 45677.355 | J646: 45677.38 | K646: 45677.38 | L646: 45677.381 | M646: =IF(AND(ISNUMBER(E646),ISNUMBER(G646)),(G646-E646),"") | N646: =IF(AND(ISNUMBER(G646),ISNUMBER(L646)),(L646-G646),"") | O646: 45674.859 | P646: =IF(AND(ISNUMBER(I646),ISNUMBER(O646)),(I646-O646),"") | Q646: WG 1017402 entered track and got secured then waited 4:15:42 for WG 1017502 to get coupled then waited 0:02:04 for WG 1017504 to get coupled, OBTP started on 08:31:27 finished on 09:07:17 and then left at 09:08:29
A647: 1017403 | B647: 10174 | C647: 19.9 | D647: Ternitz (Schoeller-Bleckmann) | E647: 45674.84 | F647: 45674.857 | G647: 45674.859 | H647: OBT170125205009-Ternitz (Schoeller-Bleckmann) | I647: 45677.321 | J647: 45677.352 | K647: 45677.352 | L647: 45677.353 | M647: =IF(AND(ISNUMBER(E647),ISNUMBER(G647)),(G647-E647),"") | N647: =IF(AND(ISNUMBER(G647),ISNUMBER(L647)),(L647-G647),"") | O647: 45674.861 | P647: =IF(AND(ISNUMBER(I647),ISNUMBER(O647)),(I647-O647),"") | Q647: WG 1017403 entered track and got secured then waited 0:09:44 for WG 1017406 to get coupled, OBTP started on 07:42:36 finished on 08:26:33 and then left at 08:27:55
A648: 1017404 | B648: 10174 | C648: 54 | D648: Wr. Neustadt (Hödlmayr) | E648: 45674.84 | F648: 45674.859 | G648: 45674.86 | H648: OBT200125080717-Wr. Neustadt (Hödlmayr) | I648: 45677.672 | J648: 45677.696 | K648: 45677.696 | L648: 45677.697 | M648: =IF(AND(ISNUMBER(E648),ISNUMBER(G648)),(G648-E648),"") | N648: =IF(AND(ISNUMBER(G648),ISNUMBER(L648)),(L648-G648),"") | O648: 45674.863 | P648: =IF(AND(ISNUMBER(I648),ISNUMBER(O648)),(I648-O648),"") | Q648: WG 1017404 entered track and got secured then waited 10:29:28 for WG 1017706 to get coupled then waited 48:55:43 for WG 1018303 to get coupled, OBTP started on 16:08:01 finished on 16:41:46 and then left at 16:43:00
A649: 1017405 | B649: 10174 | C649: 23.24 | D649: Other sidings north | E649: 45674.84 | F649: 45674.86 | G649: 45674.862 | H649: OBT190125203024-Pitten (Hamburger) | I649: 45677.457 | J649: 45677.48 | K649: 45677.48 | L649: 45677.481 | M649: =IF(AND(ISNUMBER(E649),ISNUMBER(G649)),(G649-E649),"") | N649: =IF(AND(ISNUMBER(G649),ISNUMBER(L649)),(L649-G649),"") | O649: 45674.865 | P649: =IF(AND(ISNUMBER(I649),ISNUMBER(O649)),(I649-O649),"") | Q649: WG 1017405 entered track and got secured then waited 10:29:16 for WG 1017707 to get coupled then waited 37:15:58 for WG 1017901 to get coupled, OBTP started on 10:57:50 finished on 11:31:00 and then left at 11:32:00
A650: 1017406 | B650: 10174 | C650: 155.92 | D650: Pitten (Hamburger) | E650: 45674.84 | F650: 45674.862 | G650: 45674.865 | H650: OBT170125205009-Ternitz (Schoeller-Bleckmann) | I650: 45677.321 | J650: 45677.352 | K650: 45677.352 | L650: 45677.353 | M650: =IF(AND(ISNUMBER(E650),ISNUMBER(G650)),(G650-E650),"") | N650: =IF(AND(ISNUMBER(G650),ISNUMBER(L650)),(L650-G650),"") | O650: 45674.868 | P650: =IF(AND(ISNUMBER(I650),ISNUMBER(O650)),(I650-O650),"") | Q650: WG 1017406 entered track and got coupled to WG 1017403, OBTP started on 07:42:36 finished on 08:26:33 and then left at 08:27:55
A651: 1017407 | B651: 10174 | C651: 19.9 | D651: Felixdorf/Sollenau (Bundesheer, Maba) | E651: 45674.84 | F651: 45674.865 | G651: 45674.866 | H651: OBT220125180146-Felixdorf/Sollenau (Bundesheer, Maba) | I651: 45680.651 | J651: 45680.672 | K651: 45680.672 | L651: 45680.672 | M651: =IF(AND(ISNUMBER(E651),ISNUMBER(G651)),(G651-E651),"") | N651: =IF(AND(ISNUMBER(G651),ISNUMBER(L651)),(L651-G651),"") | O651: 45674.87 | P651: =IF(AND(ISNUMBER(I651),ISNUMBER(O651)),(I651-O651),"") | Q651: WG 1017407 entered track and got coupled to WG 1016703 then waited 66:48:34 for WG 1019101 to get coupled then waited 23:30:38 for WG 1020502 to get coupled then waited 18:47:48 for WG 1021507 to get coupled then waited 8:01:57 for WG 1021902 to get coupled, OBTP started on 15:37:07 finished on 16:06:58 and then left at 16:08:09
A652: 1017408 | B652: 10174 | C652: 19.9 | D652: Neunkirchen (loading tracks) | E652: 45674.84 | M652: =IF(AND(ISNUMBER(E652),ISNUMBER(G652)),(G652-E652),"") | N652: =IF(AND(ISNUMBER(G652),ISNUMBER(L652)),(L652-G652),"") | P652: =IF(AND(ISNUMBER(I652),ISNUMBER(O652)),(I652-O652),"")
A653: 1017501 | B653: 10175 | C653: 179.16 | D653: Pitten (Hamburger) | E653: 45675.019 | F653: 45675.029 | G653: 45675.031 | H653: OBT180125004751-Pitten (Hamburger) | I653: 45677.323 | J653: 45677.354 | K653: 45677.354 | L653: 45677.355 | M653: =IF(AND(ISNUMBER(E653),ISNUMBER(G653)),(G653-E653),"") | N653: =IF(AND(ISNUMBER(G653),ISNUMBER(L653)),(L653-G653),"") | O653: 45675.033 | P653: =IF(AND(ISNUMBER(I653),ISNUMBER(O653)),(I653-O653),"") | Q653: WG 1017501 entered track and got secured, OBTP started on 07:44:51 finished on 08:29:39 and then left at 08:31:01
A654: 1017502 | B654: 10175 | C654: 54 | D654: Neudörfl (FunderMax) | E654: 45675.019 | F654: 45675.031 | G654: 45675.033 | H654: OBT180125005504-Neudörfl (FunderMax) | I654: 45677.355 | J654: 45677.38 | K654: 45677.38 | L654: 45677.381 | M654: =IF(AND(ISNUMBER(E654),ISNUMBER(G654)),(G654-E654),"") | N654: =IF(AND(ISNUMBER(G654),ISNUMBER(L654)),(L654-G654),"") | O654: 45675.037 | P654: =IF(AND(ISNUMBER(I654),ISNUMBER(O654)),(I654-O654),"") | Q654: WG 1017502 entered track and got coupled to WG 1017402 then waited 0:02:04 for WG 1017504 to get coupled, OBTP started on 08:31:27 finished on 09:07:17 and then left at 09:08:29
A655: 1017503 | B655: 10175 | C655: 85.46 | D655: Pitten (Hamburger) | E655: 45675.019 | M655: =IF(AND(ISNUMBER(E655),ISNUMBER(G655)),(G655-E655),"") | N655: =IF(AND(ISNUMBER(G655),ISNUMBER(L655)),(L655-G655),"") | P655: =IF(AND(ISNUMBER(I655),ISNUMBER(O655)),(I655-O655),"")
A656: 1017504 | B656: 10175 | C656: 52.9 | D656: Neudörfl (FunderMax) | E656: 45675.019 | F656: 45675.033 | G656: 45675.035 | H656: OBT180125005504-Neudörfl (FunderMax) | I656: 45677.355 | J656: 45677.38 | K656: 45677.38 | L656: 45677.381 | M656: =IF(AND(ISNUMBER(E656),ISNUMBER(G656)),(G656-E656),"") | N656: =IF(AND(ISNUMBER(G656),ISNUMBER(L656)),(L656-G656),"") | O656: 45675.038 | P656: =IF(AND(ISNUMBER(I656),ISNUMBER(O656)),(I656-O656),"") | Q656: WG 1017504 entered track and got coupled to WG 1017502, OBTP started on 08:31:27 finished on 09:07:17 and then left at 09:08:29
A657: 1017601 | B657: 10176 | C657: 31.48 | D657: Ebenfurth (beet loading) | E657: 45675.24 | F657: 45675.249 | G657: 45675.251 | H657: OBT200125045059-Neudörfl (FunderMax) | I657: 45677.666 | J657: 45677.723 | K657: 45677.723 | L657: 45677.725 | M657: =IF(AND(ISNUMBER(E657),ISNUMBER(G657)),(G657-E657),"") | N657: =IF(AND(ISNUMBER(G657),ISNUMBER(L657)),(L657-G657),"") | O657: 45675.255 | P657: =IF(AND(ISNUMBER(I657),ISNUMBER(O657)),(I657-O657),"") | Q657: WG 1017601 entered track and got coupled to WG 1017401 then waited 0:53:12 for WG 1017701 to get coupled then waited 45:50:13 for WG 1018101 to get coupled, OBTP started on 15:59:05 finished on 17:21:30 and then left at 17:23:20
A658: 1017602 | B658: 10176 | C658: 93.8 | D658: Neudörfl (FunderMax) | E658: 45675.24 | F658: 45675.251 | G658: 45675.253 | H658: OBT180125071607-Neudörfl (FunderMax) | I658: 45677.387 | J658: 45677.406 | K658: 45677.406 | L658: 45677.407 | M658: =IF(AND(ISNUMBER(E658),ISNUMBER(G658)),(G658-E658),"") | N658: =IF(AND(ISNUMBER(G658),ISNUMBER(L658)),(L658-G658),"") | O658: 45675.255 | P658: =IF(AND(ISNUMBER(I658),ISNUMBER(O658)),(I658-O658),"") | Q658: WG 1017602 entered track and got secured then waited 1:09:08 for WG 1017709 to get coupled, OBTP started on 09:17:40 finished on 09:45:14 and then left at 09:46:17
A659: 1017603 | B659: 10176 | C659: 287.86 | D659: Pitten (Hamburger) | E659: 45675.24 | M659: =IF(AND(ISNUMBER(E659),ISNUMBER(G659)),(G659-E659),"") | N659: =IF(AND(ISNUMBER(G659),ISNUMBER(L659)),(L659-G659),"") | P659: =IF(AND(ISNUMBER(I659),ISNUMBER(O659)),(I659-O659),"")
A660: 1017701 | B660: 10177 | C660: 47.22 | D660: Ebenfurth (beet loading) | E660: 45675.27 | F660: 45675.287 | G660: 45675.289 | H660: OBT200125045059-Neudörfl (FunderMax) | I660: 45677.666 | J660: 45677.723 | K660: 45677.723 | L660: 45677.725 | M660: =IF(AND(ISNUMBER(E660),ISNUMBER(G660)),(G660-E660),"") | N660: =IF(AND(ISNUMBER(G660),ISNUMBER(L660)),(L660-G660),"") | O660: 45675.292 | P660: =IF(AND(ISNUMBER(I660),ISNUMBER(O660)),(I660-O660),"") | Q660: WG 1017701 entered track and got coupled to WG 1017601 then waited 45:50:13 for WG 1018101 to get coupled, OBTP started on 15:59:05 finished on 17:21:30 and then left at 17:23:20
A661: 1017702 | B661: 10177 | C661: 21 | D661: Neunkirchen (loading tracks) | E661: 45675.27 | M661: =IF(AND(ISNUMBER(E661),ISNUMBER(G661)),(G661-E661),"") | N661: =IF(AND(ISNUMBER(G661),ISNUMBER(L661)),(L661-G661),"") | P661: =IF(AND(ISNUMBER(I661),ISNUMBER(O661)),(I661-O661),"")
A662: 1017703 | B662: 10177 | C662: 31.48 | D662: Gloggnitz | E662: 45675.27 | F662: 45675.289 | G662: 45675.291 | H662: OBT190125175511-Pitten (Hamburger) | I662: 45677.409 | J662: 45677.5 | K662: 45677.5 | L662: 45677.501 | M662: =IF(AND(ISNUMBER(E662),ISNUMBER(G662)),(G662-E662),"") | N662: =IF(AND(ISNUMBER(G662),ISNUMBER(L662)),(L662-G662),"") | O662: 45675.293 | P662: =IF(AND(ISNUMBER(I662),ISNUMBER(O662)),(I662-O662),"") | Q662: WG 1017703 entered track and got secured then waited 34:53:18 for WG 1017801 to get coupled, OBTP started on 09:49:25 finished on 11:59:51 and then left at 12:02:09
...

Sheet Outbound Trains
A1: ID | B1: Destination | C1: Length (m) | D1: Track | E1: OBTP init | F1: OBTP starts | G1: OBTP ends | H1: Departure drive init | I1: Departure drive starts | J1: Departure drive ends | K1: OBTP wait (hh:mm:ss) | L1: OBTP duration (hh:mm:ss) | M1: DEPD gate wait (hh:mm:ss) | N1: DEPD duration (hh:mm:ss) | O1: Total on classification track (hh:mm:ss)
A2: OBT020125030112-Neunkirchen (loading tracks) | B2: Neunkirchen (loading tracks) | C2: 103.9 | D2: 613 | E2: 45659.126 | F2: 45659.127 | G2: 45659.145 | H2: 45659.145 | I2: 45659.145 | J2: 45659.145 | K2: =IF(AND(ISNUMBER(E2),ISNUMBER(F2)),(F2-E2),"") | L2: =IF(AND(ISNUMBER(F2),ISNUMBER(G2)),(G2-F2),"") | M2: =IF(AND(ISNUMBER(H2),ISNUMBER(I2)),(I2-H2),"") | N2: =IF(AND(ISNUMBER(I2),ISNUMBER(J2)),(J2-I2),"") | O2: =IF(AND(ISNUMBER(E2),ISNUMBER(J2)),(J2-E2),"")
A3: OBT020125064334-Wien Kledering | B3: Wien Kledering | C3: 182.7 | D3: 613 | E3: 45659.28 | F3: 45659.281 | G3: 45659.313 | H3: 45659.313 | I3: 45659.313 | J3: 45659.314 | K3: =IF(AND(ISNUMBER(E3),ISNUMBER(F3)),(F3-E3),"") | L3: =IF(AND(ISNUMBER(F3),ISNUMBER(G3)),(G3-F3),"") | M3: =IF(AND(ISNUMBER(H3),ISNUMBER(I3)),(I3-H3),"") | N3: =IF(AND(ISNUMBER(I3),ISNUMBER(J3)),(J3-I3),"") | O3: =IF(AND(ISNUMBER(E3),ISNUMBER(J3)),(J3-E3),"")
A4: OBT020125073857-Wien Kledering | B4: Wien Kledering | C4: 188.96 | D4: 621 | E4: 45659.319 | F4: 45659.32 | G4: 45659.352 | H4: 45659.352 | I4: 45659.352 | J4: 45659.353 | K4: =IF(AND(ISNUMBER(E4),ISNUMBER(F4)),(F4-E4),"") | L4: =IF(AND(ISNUMBER(F4),ISNUMBER(G4)),(G4-F4),"") | M4: =IF(AND(ISNUMBER(H4),ISNUMBER(I4)),(I4-H4),"") | N4: =IF(AND(ISNUMBER(I4),ISNUMBER(J4)),(J4-I4),"") | O4: =IF(AND(ISNUMBER(E4),ISNUMBER(J4)),(J4-E4),"")
A5: OBT020125074750-Pitten (Hamburger) | B5: Pitten (Hamburger) | C5: 264.62 | D5: 605 | E5: 45659.325 | F5: 45659.326 | G5: 45659.372 | H5: 45659.372 | I5: 45659.372 | J5: 45659.373 | K5: =IF(AND(ISNUMBER(E5),ISNUMBER(F5)),(F5-E5),"") | L5: =IF(AND(ISNUMBER(F5),ISNUMBER(G5)),(G5-F5),"") | M5: =IF(AND(ISNUMBER(H5),ISNUMBER(I5)),(I5-H5),"") | N5: =IF(AND(ISNUMBER(I5),ISNUMBER(J5)),(J5-I5),"") | O5: =IF(AND(ISNUMBER(E5),ISNUMBER(J5)),(J5-E5),"")
A6: OBT020125082044-Wien Kledering | B6: Wien Kledering | C6: 396.56 | D6: 613 | E6: 45659.348 | F6: 45659.349 | G6: 45659.418 | H6: 45659.418 | I6: 45659.418 | J6: 45659.42 | K6: =IF(AND(ISNUMBER(E6),ISNUMBER(F6)),(F6-E6),"") | L6: =IF(AND(ISNUMBER(F6),ISNUMBER(G6)),(G6-F6),"") | M6: =IF(AND(ISNUMBER(H6),ISNUMBER(I6)),(I6-H6),"") | N6: =IF(AND(ISNUMBER(I6),ISNUMBER(J6)),(J6-I6),"") | O6: =IF(AND(ISNUMBER(E6),ISNUMBER(J6)),(J6-E6),"")
A7: OBT020125092035-Wien Kledering | B7: Wien Kledering | C7: 142.2 | D7: 629 | E7: 45659.389 | F7: 45659.39 | G7: 45659.415 | H7: 45659.415 | I7: 45659.415 | J7: 45659.416 | K7: =IF(AND(ISNUMBER(E7),ISNUMBER(F7)),(F7-E7),"") | L7: =IF(AND(ISNUMBER(F7),ISNUMBER(G7)),(G7-F7),"") | M7: =IF(AND(ISNUMBER(H7),ISNUMBER(I7)),(I7-H7),"") | N7: =IF(AND(ISNUMBER(I7),ISNUMBER(J7)),(J7-I7),"") | O7: =IF(AND(ISNUMBER(E7),ISNUMBER(J7)),(J7-E7),"")
A8: OBT020125093208-Other sidings north | B8: Other sidings north | C8: 134.24 | D8: 619 | E8: 45659.397 | F8: 45659.414 | G8: 45659.438 | H8: 45659.438 | I8: 45659.438 | J8: 45659.438 | K8: =IF(AND(ISNUMBER(E8),ISNUMBER(F8)),(F8-E8),"") | L8: =IF(AND(ISNUMBER(F8),ISNUMBER(G8)),(G8-F8),"") | M8: =IF(AND(ISNUMBER(H8),ISNUMBER(I8)),(I8-H8),"") | N8: =IF(AND(ISNUMBER(I8),ISNUMBER(J8)),(J8-I8),"") | O8: =IF(AND(ISNUMBER(E8),ISNUMBER(J8)),(J8-E8),"")
A9: OBT020125093825-Wr. Neustadt (Hödlmayr) | B9: Wr. Neustadt (Hödlmayr) | C9: 108 | D9: 609 | E9: 45659.402 | F9: 45659.416 | G9: 45659.435 | H9: 45659.435 | I9: 45659.435 | J9: 45659.436 | K9: =IF(AND(ISNUMBER(E9),ISNUMBER(F9)),(F9-E9),"") | L9: =IF(AND(ISNUMBER(F9),ISNUMBER(G9)),(G9-F9),"") | M9: =IF(AND(ISNUMBER(H9),ISNUMBER(I9)),(I9-H9),"") | N9: =IF(AND(ISNUMBER(I9),ISNUMBER(J9)),(J9-I9),"") | O9: =IF(AND(ISNUMBER(E9),ISNUMBER(J9)),(J9-E9),"")
A10: OBT020125094857-Pitten (Hamburger) | B10: Pitten (Hamburger) | C10: 194.16 | D10: 629 | E10: 45659.409 | F10: 45659.42 | G10: 45659.454 | H10: 45659.454 | I10: 45659.454 | J10: 45659.455 | K10: =IF(AND(ISNUMBER(E10),ISNUMBER(F10)),(F10-E10),"") | L10: =IF(AND(ISNUMBER(F10),ISNUMBER(G10)),(G10-F10),"") | M10: =IF(AND(ISNUMBER(H10),ISNUMBER(I10)),(I10-H10),"") | N10: =IF(AND(ISNUMBER(I10),ISNUMBER(J10)),(J10-I10),"") | O10: =IF(AND(ISNUMBER(E10),ISNUMBER(J10)),(J10-E10),"")
A11: OBT020125105809-Wien Kledering | B11: Wien Kledering | C11: 367.16 | D11: 613 | E11: 45659.457 | F11: 45659.458 | G11: 45659.522 | H11: 45659.522 | I11: 45659.522 | J11: 45659.523 | K11: =IF(AND(ISNUMBER(E11),ISNUMBER(F11)),(F11-E11),"") | L11: =IF(AND(ISNUMBER(F11),ISNUMBER(G11)),(G11-F11),"") | M11: =IF(AND(ISNUMBER(H11),ISNUMBER(I11)),(I11-H11),"") | N11: =IF(AND(ISNUMBER(I11),ISNUMBER(J11)),(J11-I11),"") | O11: =IF(AND(ISNUMBER(E11),ISNUMBER(J11)),(J11-E11),"")
A12: OBT020125145206-Wien Kledering | B12: Wien Kledering | C12: 287.12 | D12: 613 | E12: 45659.62 | F12: 45659.62 | G12: 45659.67 | H12: 45659.67 | I12: 45659.67 | J12: 45659.671 | K12: =IF(AND(ISNUMBER(E12),ISNUMBER(F12)),(F12-E12),"") | L12: =IF(AND(ISNUMBER(F12),ISNUMBER(G12)),(G12-F12),"") | M12: =IF(AND(ISNUMBER(H12),ISNUMBER(I12)),(I12-H12),"") | N12: =IF(AND(ISNUMBER(I12),ISNUMBER(J12)),(J12-I12),"") | O12: =IF(AND(ISNUMBER(E12),ISNUMBER(J12)),(J12-E12),"")
A13: OBT020125152222-Ternitz (Schoeller-Bleckmann) | B13: Ternitz (Schoeller-Bleckmann) | C13: 363.4 | D13: 627 | E13: 45659.641 | F13: 45659.641 | G13: 45659.704 | H13: 45659.704 | I13: 45659.705 | J13: 45659.706 | K13: =IF(AND(ISNUMBER(E13),ISNUMBER(F13)),(F13-E13),"") | L13: =IF(AND(ISNUMBER(F13),ISNUMBER(G13)),(G13-F13),"") | M13: =IF(AND(ISNUMBER(H13),ISNUMBER(I13)),(I13-H13),"") | N13: =IF(AND(ISNUMBER(I13),ISNUMBER(J13)),(J13-I13),"") | O13: =IF(AND(ISNUMBER(E13),ISNUMBER(J13)),(J13-E13),"")
... A411: OBT310125080145-Wr. Neustadt (Brenntag) | B411: Wr. Neustadt (Brenntag) | C411: 115.7 | D411: 619 | E411: 45688.335 | F411: 45688.864 | G411: 45688.884 | H411: 45688.884 | I411: 45688.884 | J411: 45688.885 | K411: =IF(AND(ISNUMBER(E411),ISNUMBER(F411)),(F411-E411),"") | L411: =IF(AND(ISNUMBER(F411),ISNUMBER(G411)),(G411-F411),"") | M411: =IF(AND(ISNUMBER(H411),ISNUMBER(I411)),(I411-H411),"") | N411: =IF(AND(ISNUMBER(I411),ISNUMBER(J411)),(J411-I411),"") | O411: =IF(AND(ISNUMBER(E411),ISNUMBER(J411)),(J411-E411),"")
A412: OBT310125082055-Wien Kledering | B412: Wien Kledering | C412: 381.56 | D412: 627 | E412: 45688.348 | K412: =IF(AND(ISNUMBER(E412),ISNUMBER(F412)),(F412-E412),"") | L412: =IF(AND(ISNUMBER(F412),ISNUMBER(G412)),(G412-F412),"") | M412: =IF(AND(ISNUMBER(H412),ISNUMBER(I412)),(I412-H412),"") | N412: =IF(AND(ISNUMBER(I412),ISNUMBER(J412)),(J412-I412),"") | O412: =IF(AND(ISNUMBER(E412),ISNUMBER(J412)),(J412-E412),"")
A413: OBT310125091105-Wien Kledering | B413: Wien Kledering | C413: 164.3 | D413: 627 | E413: 45688.383 | K413: =IF(AND(ISNUMBER(E413),ISNUMBER(F413)),(F413-E413),"") | L413: =IF(AND(ISNUMBER(F413),ISNUMBER(G413)),(G413-F413),"") | M413: =IF(AND(ISNUMBER(H413),ISNUMBER(I413)),(I413-H413),"") | N413: =IF(AND(ISNUMBER(I413),ISNUMBER(J413)),(J413-I413),"") | O413: =IF(AND(ISNUMBER(E413),ISNUMBER(J413)),(J413-E413),"")
A414: OBT310125105654-Wien Kledering | B414: Wien Kledering | C414: 270.8 | D414: 627 | E414: 45688.456 | K414: =IF(AND(ISNUMBER(E414),ISNUMBER(F414)),(F414-E414),"") | L414: =IF(AND(ISNUMBER(F414),ISNUMBER(G414)),(G414-F414),"") | M414: =IF(AND(ISNUMBER(H414),ISNUMBER(I414)),(I414-H414),"") | N414: =IF(AND(ISNUMBER(I414),ISNUMBER(J414)),(J414-I414),"") | O414: =IF(AND(ISNUMBER(E414),ISNUMBER(J414)),(J414-E414),"")
A415: OBT310125110109-St. Veit an der Glan | B415: St. Veit an der Glan | C415: 155.7 | D415: 617 | E415: 45688.459 | K415: =IF(AND(ISNUMBER(E415),ISNUMBER(F415)),(F415-E415),"") | L415: =IF(AND(ISNUMBER(F415),ISNUMBER(G415)),(G415-F415),"") | M415: =IF(AND(ISNUMBER(H415),ISNUMBER(I415)),(I415-H415),"") | N415: =IF(AND(ISNUMBER(I415),ISNUMBER(J415)),(J415-I415),"") | O415: =IF(AND(ISNUMBER(E415),ISNUMBER(J415)),(J415-E415),"")
A416: OBT310125124603-Wien Kledering | B416: Wien Kledering | C416: 339 | D416: 607 | E416: 45688.532 | K416: =IF(AND(ISNUMBER(E416),ISNUMBER(F416)),(F416-E416),"") | L416: =IF(AND(ISNUMBER(F416),ISNUMBER(G416)),(G416-F416),"") | M416: =IF(AND(ISNUMBER(H416),ISNUMBER(I416)),(I416-H416),"") | N416: =IF(AND(ISNUMBER(I416),ISNUMBER(J416)),(J416-I416),"") | O416: =IF(AND(ISNUMBER(E416),ISNUMBER(J416)),(J416-E416),"")
A417: OBT310125142730-Wien Kledering | B417: Wien Kledering | C417: 186.66 | D417: 615 | E417: 45688.602 | K417: =IF(AND(ISNUMBER(E417),ISNUMBER(F417)),(F417-E417),"") | L417: =IF(AND(ISNUMBER(F417),ISNUMBER(G417)),(G417-F417),"") | M417: =IF(AND(ISNUMBER(H417),ISNUMBER(I417)),(I417-H417),"") | N417: =IF(AND(ISNUMBER(I417),ISNUMBER(J417)),(J417-I417),"") | O417: =IF(AND(ISNUMBER(E417),ISNUMBER(J417)),(J417-E417),"")
A418: OBT310125155632-Pitten (Hamburger) | B418: Pitten (Hamburger) | C418: 157.24 | D418: 621 | E418: 45688.664 | K418: =IF(AND(ISNUMBER(E418),ISNUMBER(F418)),(F418-E418),"") | L418: =IF(AND(ISNUMBER(F418),ISNUMBER(G418)),(G418-F418),"") | M418: =IF(AND(ISNUMBER(H418),ISNUMBER(I418)),(I418-H418),"") | N418: =IF(AND(ISNUMBER(I418),ISNUMBER(J418)),(J418-I418),"") | O418: =IF(AND(ISNUMBER(E418),ISNUMBER(J418)),(J418-E418),"")
A419: OBT310125155832-Neudörfl (FunderMax) | B419: Neudörfl (FunderMax) | C419: 115.9 | D419: 611 | E419: 45688.666 | K419: =IF(AND(ISNUMBER(E419),ISNUMBER(F419)),(F419-E419),"") | L419: =IF(AND(ISNUMBER(F419),ISNUMBER(G419)),(G419-F419),"") | M419: =IF(AND(ISNUMBER(H419),ISNUMBER(I419)),(I419-H419),"") | N419: =IF(AND(ISNUMBER(I419),ISNUMBER(J419)),(J419-I419),"") | O419: =IF(AND(ISNUMBER(E419),ISNUMBER(J419)),(J419-E419),"")
A420: OBT310125160801-Other sidings north | B420: Other sidings north | C420: 153.32 | D420: 629 | E420: 45688.672 | K420: =IF(AND(ISNUMBER(E420),ISNUMBER(F420)),(F420-E420),"") | L420: =IF(AND(ISNUMBER(F420),ISNUMBER(G420)),(G420-F420),"") | M420: =IF(AND(ISNUMBER(H420),ISNUMBER(I420)),(I420-H420),"") | N420: =IF(AND(ISNUMBER(I420),ISNUMBER(J420)),(J420-I420),"") | O420: =IF(AND(ISNUMBER(E420),ISNUMBER(J420)),(J420-E420),"")
A421: OBT310125161451-Steinabrückl/Wöllersdorf | B421: Steinabrückl/Wöllersdorf | C421: 110.18 | D421: 623 | E421: 45688.677 | K421: =IF(AND(ISNUMBER(E421),ISNUMBER(F421)),(F421-E421),"") | L421: =IF(AND(ISNUMBER(F421),ISNUMBER(G421)),(G421-F421),"") | M421: =IF(AND(ISNUMBER(H421),ISNUMBER(I421)),(I421-H421),"") | N421: =IF(AND(ISNUMBER(I421),ISNUMBER(J421)),(J421-I421),"") | O421: =IF(AND(ISNUMBER(E421),ISNUMBER(J421)),(J421-E421),"")
A422: OBT310125162356-Other sidings south | B422: Other sidings south | C422: 106.1 | D422: 609 | E422: 45688.683 | K422: =IF(AND(ISNUMBER(E422),ISNUMBER(F422)),(F422-E422),"") | L422: =IF(AND(ISNUMBER(F422),ISNUMBER(G422)),(G422-F422),"") | M422: =IF(AND(ISNUMBER(H422),ISNUMBER(I422)),(I422-H422),"") | N422: =IF(AND(ISNUMBER(I422),ISNUMBER(J422)),(J422-I422),"") | O422: =IF(AND(ISNUMBER(E422),ISNUMBER(J422)),(J422-E422),"")
A423: OBT310125174917-Wien Kledering | B423: Wien Kledering | C423: 302.12 | D423: 613 | E423: 45688.743 | K423: =IF(AND(ISNUMBER(E423),ISNUMBER(F423)),(F423-E423),"") | L423: =IF(AND(ISNUMBER(F423),ISNUMBER(G423)),(G423-F423),"") | M423: =IF(AND(ISNUMBER(H423),ISNUMBER(I423)),(I423-H423),"") | N423: =IF(AND(ISNUMBER(I423),ISNUMBER(J423)),(J423-I423),"") | O423: =IF(AND(ISNUMBER(E423),ISNUMBER(J423)),(J423-E423),"")
... A427: OBT310125204436-Other sidings south | B427: Other sidings south | C427: 126 | D427: 629 | E427: 45688.864 | K427: =IF(AND(ISNUMBER(E427),ISNUMBER(F427)),(F427-E427),"") | L427: =IF(AND(ISNUMBER(F427),ISNUMBER(G427)),(G427-F427),"") | M427: =IF(AND(ISNUMBER(H427),ISNUMBER(I427)),(I427-H427),"") | N427: =IF(AND(ISNUMBER(I427),ISNUMBER(J427)),(J427-I427),"") | O427: =IF(AND(ISNUMBER(E427),ISNUMBER(J427)),(J427-E427),"")

Sheet Drive Stats
A1: Activity Type | B1: From | C1: To | D1: Count | E1: Mean Dist (m) | F1: Min Dist (m) | G1: Max Dist (m) | H1: Mean Duration (hh:mm:ss) | I1: Min Duration (hh:mm:ss) | J1: Max Duration (hh:mm:ss) | K1: Mean Speed (km/h) | L1: Min Speed (km/h) | M1: Max Speed (km/h) | N1: Speed Std (km/h)
A2: ArrivalDrive | B2: Entry gate | C2: 703 | D2: 239 | E2: 766.25 | F2: 766.25 | G2: 766.25 | H2: 0.0023043546 | I2: 0.0017592593 | J2: 0.0028009259 | K2: 14.009485 | L2: 11.39876 | M2: 18.148026 | N2: 1.5087117
A3: ArrivalDrive | B3: Entry gate | C3: 725 | D3: 7 | E3: 476.05 | F3: 476.05 | G3: 476.05 | H3: 0.0019196429 | I3: 0.0012384259 | J3: 0.0023726852 | K3: 10.957028 | L3: 8.3599024 | M3: 16.016636 | N3: 2.7942526
A4: ArrivalDrive | B4: Entry gate | C4: 727 | D4: 66 | E4: 556.2 | F4: 556.2 | G4: 556.2 | H4: 0.002081229 | I4: 0.0013888889 | J4: 0.0025231481 | K4: 11.508503 | L4: 9.1849541 | M4: 16.686 | N4: 2.1943055
A5: ArrivalDrive | B5: Entry gate | C5: 731 | D5: 19 | E5: 587.14 | F5: 587.14 | G5: 587.14 | H5: 0.001306652 | I5: 0.00125 | J5: 0.0013657407 | K5: 18.746789 | L5: 17.912746 | M5: 19.571333 | N5: 0.67126292
A6: DepartureDrive | B6: 605 | C6: Exit gate | D6: 30 | E6: 286.14 | F6: 286.14 | G6: 286.14 | H6: 0.001001929 | I6: 0.00084490741 | J6: 0.0015509259 | K6: 12.149625 | L6: 7.6873433 | M6: 14.111014 | N6: 1.6024438
A7: DepartureDrive | B7: 606 | C7: Exit gate | D7: 18 | E7: 245 | F7: 245 | G7: 245 | H7: 0.00098186728 | I7: 0.00076388889 | J7: 0.0013888889 | K7: 10.768632 | L7: 7.35 | M7: 13.363636 | N7: 1.9207925
A8: DepartureDrive | B8: 607 | C8: Exit gate | D8: 17 | E8: 286.14 | F8: 286.14 | G8: 286.14 | H8: 0.0010866013 | I8: 0.00083333333 | J8: 0.0015740741 | K8: 11.516327 | L8: 7.5742941 | M8: 14.307 | N8: 2.4182335
A9: DepartureDrive | B9: 609 | C9: Exit gate | D9: 14 | E9: 259.16 | F9: 259.16 | G9: 259.16 | H9: 0.0009672619 | I9: 0.00077546296 | J9: 0.0015972222 | K9: 11.80759 | L9: 6.7606957 | M9: 13.925015 | N9: 2.3659737
A10: DepartureDrive | B10: 611 | C10: Exit gate | D10: 22 | E10: 231.94 | F10: 231.94 | G10: 231.94 | H10: 0.0010648148 | I10: 0.00072916667 | J10: 0.0019907407 | K10: 9.8781619 | L10: 4.8545581 | M10: 13.253714 | N10: 2.5589883
A11: DepartureDrive | B11: 613 | C11: Exit gate | D11: 46 | E11: 205.9 | F11: 205.9 | G11: 205.9 | H11: 0.00097498994 | I11: 0.00065972222 | J11: 0.0015740741 | K11: 9.4686247 | L11: 5.4502941 | M11: 13.004211 | N11: 2.4813881
A12: DepartureDrive | B12: 615 | C12: Exit gate | D12: 65 | E12: 223.61 | F12: 223.61 | G12: 223.61 | H12: 0.00098272792 | I12: 0.00069444444 | J12: 0.0015046296 | K12: 9.9983424 | L12: 6.1922769 | M12: 13.4166 | N12: 2.2320292
A13: DepartureDrive | B13: 617 | C13: Exit gate | D13: 19 | E13: 262.93 | F13: 262.93 | G13: 262.93 | H13: 0.00095394737 | I13: 0.00077546296 | J13: 0.0013888889 | K13: 11.941622 | L13: 7.8879 | M13: 14.127582 | N13: 2.1577381
... A68: PushOffDrive | B68: 731 | C68: 621 | D68: 1 | E68: 544.85 | F68: 544.85 | G68: 544.85 | H68: 0.0024189815 | I68: 0.0024189815 | J68: 0.0024189815 | K68: 9.3849761 | L68: 9.3849761 | M68: 9.3849761 | N68: 0

Sheet WG Yard Times
A1: WG Id | B1: Parent Train | C1: Train Spawn | D1: Train Arrived Track | E1: WG PushOff Drive Start | F1: WG Arrived Classif | G1: Parent OBT | H1: OBT Formed | I1: OBT Leaves Classif (DEPD start) | J1: Train Exits Station | K1: Arrival Yard (hh:mm:ss) | L1: Classif Yard (hh:mm:ss) | P1: Summary (hh:mm:ss)
A2: 1000101 | B2: 10001 | C2: 45659.111 | D2: 45659.113 | E2: 45659.121 | F2: 45659.122 | G2: OBT030125061555-Other sidings south | H2: 45660.261 | I2: 45660.281 | J2: 45660.281 | K2: =IF(AND(ISNUMBER(D2),ISNUMBER(E2)),(E2-D2),"") | L2: =IF(AND(ISNUMBER(F2),ISNUMBER(I2)),(I2-F2),"") | P2: Arrival yard mean | Q2: =IFERROR(AVERAGE(K2:K1089),0)
A3: 1000102 | B3: 10001 | C3: 45659.111 | D3: 45659.113 | E3: 45659.122 | F3: 45659.124 | G3: OBT020125030112-Neunkirchen (loading tracks) | H3: 45659.126 | I3: 45659.145 | J3: 45659.145 | K3: =IF(AND(ISNUMBER(D3),ISNUMBER(E3)),(E3-D3),"") | L3: =IF(AND(ISNUMBER(F3),ISNUMBER(I3)),(I3-F3),"") | P3: Arrival yard median | Q3: =IFERROR(MEDIAN(K2:K1089),0)
A4: 1000103 | B4: 10001 | C4: 45659.111 | D4: 45659.113 | E4: 45659.124 | F4: 45659.126 | G4: OBT020125152222-Ternitz (Schoeller-Bleckmann) | H4: 45659.641 | I4: 45659.705 | J4: 45659.706 | K4: =IF(AND(ISNUMBER(D4),ISNUMBER(E4)),(E4-D4),"") | L4: =IF(AND(ISNUMBER(F4),ISNUMBER(I4)),(I4-F4),"") | P4: Arrival yard min | Q4: =IFERROR(MIN(K2:K1089),0)
A5: 1000104 | B5: 10001 | C5: 45659.111 | D5: 45659.113 | E5: 45659.126 | F5: 45659.128 | G5: OBT030125063005-Gloggnitz | H5: 45660.271 | I5: 45660.313 | J5: 45660.314 | K5: =IF(AND(ISNUMBER(D5),ISNUMBER(E5)),(E5-D5),"") | L5: =IF(AND(ISNUMBER(F5),ISNUMBER(I5)),(I5-F5),"") | P5: Arrival yard max | Q5: =IFERROR(MAX(K2:K1089),0)
A6: 1000201 | B6: 10002 | C6: 45659.269 | D6: 45659.271 | E6: 45659.276 | F6: 45659.278 | G6: OBT020125064334-Wien Kledering | H6: 45659.28 | I6: 45659.313 | J6: 45659.314 | K6: =IF(AND(ISNUMBER(D6),ISNUMBER(E6)),(E6-D6),"") | L6: =IF(AND(ISNUMBER(F6),ISNUMBER(I6)),(I6-F6),"") | P6: Classif yard mean | Q6: =IFERROR(AVERAGE(L2:L1089),0)
